<?xml version="1.0" ?>
<!-- =================================================================================== -->
<!-- |    This document was autogenerated by xacro from /home/lduchate/super_ws/src/SUPER/mars_uav_sim/perfect_drone_sim/urdf/final_iris.urdf.xacro | -->
<!-- |    EDITING THIS FILE BY HAND IS NOT RECOMMENDED                                 | -->
<!-- =================================================================================== -->
<robot name="final_iris">
  <!-- Dummy link -->
  <link name="dummy_link"/>
  <!-- Fixed joint between dummy_link and base_link 0.195-->
  <joint name="fixed_joint" type="fixed">
    <parent link="dummy_link"/>
    <child link="base_link"/>
    <origin xyz="0 0 0.195" rpy="0 0 0"/>
  </joint>
  <link name="base_link">
    <inertial>
      <mass value="1.5"/>
      <origin rpy="0 0 0" xyz="0 0 0"/>
      <inertia ixx="0.008" ixy="0" ixz="0" iyy="0.015" iyz="0" izz="0.017"/>
    </inertial>
    <collision name="base_link">
      <origin rpy="0 0 0" xyz="0      0      -0.08"/>
      <geometry>
        <box size="0.47 0.47 0.23"/>
      </geometry>
    </collision>
    <visual>
      <geometry>
        <mesh filename="package://iq_sim/models/iris_base/meshes/iris.dae" scale="1.0 1.0 1.0"/>
      </geometry>
    </visual>
    <visual>
      <origin rpy="0 0 0" xyz="0.123   0.22    -0.11"/>
      <geometry>
        <cylinder length="0.17" radius="0.005"/>
      </geometry>
    </visual>
    <visual>
      <origin rpy="0 0 0" xyz="0.123   -0.22     -0.11"/>
      <geometry>
        <cylinder length="0.17" radius="0.005"/>
      </geometry>
    </visual>
    <visual>
      <origin rpy="0 0 0" xyz="-0.14     0.21     -0.11"/>
      <geometry>
        <cylinder length="0.17" radius="0.005"/>
      </geometry>
    </visual>
    <visual>
      <origin rpy="0 0 0" xyz="-0.14    -0.21     -0.11"/>
      <geometry>
        <cylinder length="0.17" radius="0.005"/>
      </geometry>
    </visual>
  </link>
  <link name="velodyne">
    <visual>
      <geometry>
        <mesh filename="package://velodyne_description/meshes/HDL32E_base.dae"/>
      </geometry>
    </visual>
    <gazebo>
      <plugin filename="libgazebo_ros_velodyne.so" name="gazebo_ros_velodyne">
        <robotNamespace>/</robotNamespace>
        <topicName>/velodyne_points</topicName>
        <frameName>velodyne</frameName>
        <minRange>0.5</minRange>
        <maxRange>100.0</maxRange>
        <minAngle>-3.1415</minAngle>
        <maxAngle>3.1415</maxAngle>
        <verticalResolution>16</verticalResolution>
        <horizontalResolution>180</horizontalResolution>
        <updateRate>10.0</updateRate>
      </plugin>
    </gazebo>
  </link>
  <joint name="velodyne_joint" type="fixed">
    <parent link="base_link"/>
    <child link="velodyne"/>
    <origin rpy="0 0 0" xyz="0 0 0.1"/>
  </joint>
  <!-- Laser -->
  <joint name="scan_joint" type="fixed">
    <parent link="base_link"/>
    <child link="base_scan"/>
    <origin rpy="0 0 0" xyz="0 0 0"/>
  </joint>
  <link name="base_scan">
    <!-- <visual>
            <geometry>
                <cylinder length="0.0315" radius="0.055"/>
            </geometry>
            <material name="yellow">
                <color rgba="1.0 1.0 0.0 1.0"/>            
            </material>
        </visual> -->
    <!-- <collision>
            <origin xyz="0.015 0 -0.0065" rpy="0 0 0"/>
                <geometry>
                    <cylinder length="0.0315" radius="0.055"/>
                </geometry>
        </collision> -->
  </link>
  <gazebo reference="base_scan">
    <material>Gazebo/Yellow</material>
    <sensor name="lidar_3d" type="gpu_ray">
      <pose>0 0 0 0 0 0</pose>
      <visualize>true</visualize>
      <update_rate>10</update_rate>
      <ray>
        <scan>
          <horizontal>
            <samples>180</samples>
            <resolution>1</resolution>
            <min_angle>-1.57</min_angle>
            <max_angle>1.57</max_angle>
          </horizontal>
          <vertical>
            <samples>15</samples>
            <resolution>1</resolution>
            <min_angle>-0.3</min_angle>
            <max_angle>0.3</max_angle>
          </vertical>
        </scan>
        <range>
          <min>0.45</min>
          <max>20</max>
          <resolution>0.015</resolution>
        </range>
        <noise>
          <type>gaussian</type>
          <mean>0.0</mean>
          <stddev>0.01</stddev>
        </noise>
      </ray>
      <plugin filename="libgazebo_ros_gpu_laser.so" name="gpu_laser">
        <topicName>/cloud_registered</topicName>
        <frameName>base_scan</frameName>
        <pointCloud>1</pointCloud>
      </plugin>
    </sensor>
  </gazebo>
  <!-- Camera Link -->
  <link name="camera_link">
    <inertial>
      <mass value="0.01"/>
      <origin rpy="0 0 0" xyz="0 0 0"/>
      <inertia ixx="0.001" ixy="0" ixz="0" iyy="0.001" iyz="0" izz="0.001"/>
    </inertial>
    <visual>
      <geometry>
        <cylinder length="0.018" radius="0.005"/>
      </geometry>
      <origin rpy="0 1.5707 0" xyz="0 0 0"/>
    </visual>
  </link>
  <!-- Fixed joint for the camera -->
  <joint name="camera_mount" type="fixed">
    <parent link="base_link"/>
    <child link="camera_link"/>
    <origin rpy="0 0 0" xyz="0 0 -0.09"/>
  </joint>
  <joint name="camera_optical_joint" type="fixed">
    <parent link="camera_link"/>
    <child link="camera_link_optical"/>
    <origin rpy="-1.5707963267948966 0.0 -1.5707963267948966" xyz="0.0 0.0 0.0"/>
  </joint>
  <link name="camera_link_optical"/>
  <!-- Camera sensor -->
  <gazebo reference="camera_link">
    <material>
        Gazebo/White
    </material>
    <sensor name="camera" type="depth">
      <pose> 0 0 0 0 0 0 </pose>
      <visualize>true</visualize>
      <update_rate>10</update_rate>
      <camera>
        <horizontal_fov>1.089</horizontal_fov>
        <image>
          <!-- <format>B8R8G8</format> -->
          <width>640</width>
          <height>480</height>
        </image>
        <clip>
          <near>0.01</near>
          <far>30.0</far>
        </clip>
      </camera>
      <plugin filename="libgazebo_ros_openni_kinect.so" name="camera_plugin">
        <baseline>0.2</baseline>
        <alwaysOn>true</alwaysOn>
        <!-- Keep this zero, update_rate in the parent <sensor> tag
                    will control the frame rate. -->
        <updateRate>0.0</updateRate>
        <cameraName>camera_ir</cameraName>
        <imageTopicName>/camera/color/image_raw</imageTopicName>
        <cameraInfoTopicName>/camera/color/camera_info</cameraInfoTopicName>
        <depthImageTopicName>/camera/depth/image_raw</depthImageTopicName>
        <depthImageCameraInfoTopicName>/camera/depth/camera_info</depthImageCameraInfoTopicName>
        <pointCloudTopicName>/camera/depth/points</pointCloudTopicName>
        <frameName>camera_link_optical</frameName>
        <pointCloudCutoff>0.01</pointCloudCutoff>
        <pointCloudCutoffMax>30.0</pointCloudCutoffMax>
        <distortionK1>0</distortionK1>
        <distortionK2>0</distortionK2>
        <distortionK3>0</distortionK3>
        <distortionT1>0</distortionT1>
        <distortionT2>0</distortionT2>
        <CxPrime>0</CxPrime>
        <Cx>0</Cx>
        <Cy>0</Cy>
        <focalLength>0</focalLength>
        <hackBaseline>0</hackBaseline>
      </plugin>
    </sensor>
  </gazebo>
  <joint name="final_iris/ground_truth/odometry_sensorgt_joint" type="revolute">
    <parent link="dummy_link"/>
    <child link="final_iris/ground_truth/odometry_sensorgt_link"/>
    <origin rpy="0 0 0" xyz="0 0 0"/>
    <axis xyz="0 0 1"/>
    <dynamics damping="1.0"/>
    <limit effort="0.0" lower="0.0" upper="0.0" velocity="0.0"/>
  </joint>
  <link name="final_iris/ground_truth/odometry_sensorgt_link">
    <inertial>
      <mass value="0.15"/>
      <origin rpy="0 0 0" xyz="0 0 0"/>
      <inertia ixx="0.0001" ixy="0" ixz="0" iyy="0.0002" iyz="0" izz="0.0002"/>
    </inertial>
  </link>
  <joint name="final_iris/imu_joint" type="revolute">
    <parent link="dummy_link"/>
    <child link="final_iris/imu_link"/>
    <origin rpy="0 0 0" xyz="0 0 0"/>
    <axis xyz="0 0 1"/>
    <dynamics damping="1.0"/>
    <limit effort="0.0" lower="0.0" upper="0.0" velocity="0.0"/>
  </joint>
  <link name="final_iris/imu_link">
    <inertial>
      <mass value="0.15"/>
      <origin rpy="0 0 0" xyz="0 0 0"/>
      <inertia ixx="0.00001" ixy="0" ixz="0" iyy="0.00002" iyz="0" izz="0.00002"/>
    </inertial>
  </link>
  <joint name="rotor_0_joint" type="revolute">
    <parent link="base_link"/>
    <child link="rotor_0"/>
    <origin rpy="0 0 0" xyz="0.13 -0.22 0.023"/>
    <axis xyz="0 0 1"/>
    <dynamics damping="0.004"/>
    <!-- <limit effort="2000.0" lower="-1e+16" upper="1e+16" velocity="838.0"/> -->
    <!-- <limit lower="-1e+16" upper="1e+16" effort="1000" velocity="100"/> -->
    <limit effort="-1" lower="-1e+16" upper="1e+16" velocity="-1"/>
    <!-- <limit lower="-1e+16" upper="1e+16" effort="0" velocity="0"/> -->
  </joint>
  <joint name="rotor_1_joint" type="revolute">
    <parent link="base_link"/>
    <child link="rotor_1"/>
    <origin rpy="0 0 0" xyz="-0.13 0.2 0.023"/>
    <axis xyz="0 0 1"/>
    <dynamics damping="0.004"/>
    <!-- <limit effort="2000.0" lower="-1e+16" upper="1e+16" velocity="838.0"/> -->
    <!-- <limit lower="-1e+16" upper="1e+16" effort="1000" velocity="100"/> -->
    <limit effort="-1" lower="-1e+16" upper="1e+16" velocity="-1"/>
    <!-- <limit lower="-1e+16" upper="1e+16" effort="0" velocity="0"/> -->
  </joint>
  <joint name="rotor_2_joint" type="revolute">
    <parent link="base_link"/>
    <child link="rotor_2"/>
    <origin rpy="0 0 0" xyz="0.13 0.22 0.023"/>
    <axis xyz="0 0 1"/>
    <dynamics damping="0.004"/>
    <!-- <limit effort="2000.0" lower="-1e+16" upper="1e+16" velocity="838.0"/> -->
    <!-- <limit lower="-1e+16" upper="1e+16" effort="1000" velocity="100"/> -->
    <limit effort="-1" lower="-1e+16" upper="1e+16" velocity="-1"/>
    <!-- <limit lower="-1e+16" upper="1e+16" effort="0" velocity="0"/> -->
  </joint>
  <joint name="rotor_3_joint" type="revolute">
    <parent link="base_link"/>
    <child link="rotor_3"/>
    <origin rpy="0 0 0" xyz="-0.13 -0.2 0.023"/>
    <axis xyz="0 0 1"/>
    <dynamics damping="0.004"/>
    <!-- <limit effort="2000.0" lower="-1e+16" upper="1e+16" velocity="838.0"/> -->
    <!-- <limit lower="-1e+16" upper="1e+16" effort="1000" velocity="100"/> -->
    <limit effort="-1" lower="-1e+16" upper="1e+16" velocity="-1"/>
    <!-- <limit lower="-1e+16" upper="1e+16" effort="0" velocity="0"/> -->
  </joint>
  <link name="rotor_0">
    <inertial>
      <mass value="0.025"/>
      <origin rpy="0 0 0" xyz="0 0 0"/>
      <inertia ixx="9.75e-06" ixy="0" ixz="0" iyy="0.000166704" iyz="0" izz="0.000167604"/>
    </inertial>
    <collision name="rotor_0">
      <origin rpy="0 0 0" xyz="0 0 0"/>
      <geometry>
        <cylinder length="0.005" radius="0.1"/>
      </geometry>
    </collision>
    <visual name="rotor_0">
      <origin rpy="0 0 0" xyz="0 0 0"/>
      <geometry>
        <mesh filename="package://iq_sim/models/iris_base/meshes/iris_prop_ccw.dae" scale="1 1 1"/>
      </geometry>
    </visual>
  </link>
  <link name="rotor_1">
    <inertial>
      <mass value="0.025"/>
      <origin rpy="0 0 0" xyz="0 0 0"/>
      <inertia ixx="9.75e-06" ixy="0" ixz="0" iyy="0.000166704" iyz="0" izz="0.000167604"/>
    </inertial>
    <collision name="rotor_1">
      <origin rpy="0 0 0" xyz="0 0 0"/>
      <geometry>
        <cylinder length="0.005" radius="0.1"/>
      </geometry>
    </collision>
    <visual name="rotor_1">
      <origin rpy="0 0 0" xyz="0 0 0"/>
      <geometry>
        <mesh filename="package://iq_sim/models/iris_base/meshes/iris_prop_ccw.dae" scale="1 1 1"/>
      </geometry>
    </visual>
  </link>
  <link name="rotor_2">
    <inertial>
      <mass value="0.025"/>
      <origin rpy="0 0 0" xyz="0 0 0"/>
      <inertia ixx="9.75e-06" ixy="0" ixz="0" iyy="0.000166704" iyz="0" izz="0.000167604"/>
    </inertial>
    <collision name="rotor_2">
      <origin rpy="0 0 0" xyz="0 0 0"/>
      <geometry>
        <cylinder length="0.005" radius="0.1"/>
      </geometry>
    </collision>
    <visual name="rotor_2">
      <origin rpy="0 0 0" xyz="0 0 0"/>
      <geometry>
        <mesh filename="package://iq_sim/models/iris_base/meshes/iris_prop_cw.dae" scale="1 1 1"/>
      </geometry>
    </visual>
  </link>
  <link name="rotor_3">
    <inertial>
      <mass value="0.025"/>
      <origin rpy="0 0 0" xyz="0 0 0"/>
      <inertia ixx="9.75e-06" ixy="0" ixz="0" iyy="0.000166704" iyz="0" izz="0.000167604"/>
    </inertial>
    <collision name="rotor_3">
      <origin rpy="0 0 0" xyz="0 0 0"/>
      <geometry>
        <cylinder length="0.005" radius="0.1"/>
      </geometry>
    </collision>
    <visual name="rotor_3">
      <origin rpy="0 0 0" xyz="0 0 0"/>
      <geometry>
        <mesh filename="package://iq_sim/models/iris_base/meshes/iris_prop_cw.dae" scale="1 1 1"/>
      </geometry>
    </visual>
  </link>
  <gazebo reference="base_link">
    <material>Gazebo/FlatBlack</material>
    <maxVel>100.0</maxVel>
    <minDepth>0.001</minDepth>
    <mu1>1.0</mu1>
    <mu2>1.0</mu2>
    <velocity_decay>
      <linear>0.0</linear>
      <angular>0.0</angular>
    </velocity_decay>
  </gazebo>
  <gazebo reference="final_iris/ground_truth/odometry_sensorgt_joint">
    <implicitSpringDamper>1</implicitSpringDamper>
  </gazebo>
  <gazebo reference="final_iris/imu_joint">
    <implicitSpringDamper>1</implicitSpringDamper>
  </gazebo>
  <gazebo reference="final_iris/imu_link">
    <sensor name="imu_sensor" type="imu">
      <pose>0 0 0 3.141593 0 0</pose>
      <always_on>1</always_on>
      <update_rate>1000.0</update_rate>
      <plugin filename="libgazebo_ros_imu_sensor.so" name="imu_plugin">
        <topicName>imu</topicName>
        <bodyName>final_iris/imu_link</bodyName>
        <updateRateHZ>10.0</updateRateHZ>
        <gaussianNoise>0.0</gaussianNoise>
        <xyzOffset>0 0 0</xyzOffset>
        <rpyOffset>0 0 0</rpyOffset>
        <frameName>final_iris/imu_link</frameName>
        <initialOrientationAsReference>false</initialOrientationAsReference>
      </plugin>
    </sensor>
  </gazebo>
  <gazebo reference="rotor_0">
    <material>Gazebo/Blue</material>
    <selfCollide>0</selfCollide>
  </gazebo>
  <gazebo reference="rotor_0_joint">
    <implicitSpringDamper>1</implicitSpringDamper>
  </gazebo>
  <gazebo reference="rotor_1">
    <material>Gazebo/DarkGrey</material>
    <selfCollide>0</selfCollide>
  </gazebo>
  <gazebo reference="rotor_1_joint">
    <implicitSpringDamper>1</implicitSpringDamper>
  </gazebo>
  <gazebo reference="rotor_2">
    <material>Gazebo/Blue</material>
    <selfCollide>0</selfCollide>
  </gazebo>
  <gazebo reference="rotor_2_joint">
    <implicitSpringDamper>1</implicitSpringDamper>
  </gazebo>
  <gazebo reference="rotor_3">
    <material>Gazebo/DarkGrey</material>
    <selfCollide>0</selfCollide>
  </gazebo>
  <gazebo reference="rotor_3_joint">
    <implicitSpringDamper>1</implicitSpringDamper>
  </gazebo>
  <gazebo>
    <plugin filename="libLiftDragPlugin.so" name="rotor_0_blade_1">
      <a0>0.1</a0>
      <alpha_stall>1.4</alpha_stall>
      <cla>0.2500</cla>
      <cda>0.10</cda>
      <cma>0.00</cma>
      <cla_stall>-0.025</cla_stall>
      <cda_stall>0.0</cda_stall>
      <cma_stall>0.0</cma_stall>
      <area>0.2</area>
      <air_density>1.2041</air_density>
      <cp>0.084 0 0</cp>
      <forward>0 1 0</forward>
      <upward>0 0 1</upward>
      <link_name>final_iris::rotor_0</link_name>
    </plugin>
  </gazebo>
  <gazebo>
    <plugin filename="libLiftDragPlugin.so" name="rotor_0_blade_2">
      <a0>0.1</a0>
      <alpha_stall>1.4</alpha_stall>
      <cla>0.2500</cla>
      <cda>0.10</cda>
      <cma>0.00</cma>
      <cla_stall>-0.025</cla_stall>
      <cda_stall>0.0</cda_stall>
      <cma_stall>0.0</cma_stall>
      <area>0.2</area>
      <air_density>1.2041</air_density>
      <cp>-0.084 0 0</cp>
      <forward>0 -1 0</forward>
      <upward>0 0 1</upward>
      <link_name>final_iris::rotor_0</link_name>
    </plugin>
  </gazebo>
  <gazebo>
    <plugin filename="libLiftDragPlugin.so" name="rotor_1_blade_1">
      <a0>0.1</a0>
      <alpha_stall>1.4</alpha_stall>
      <cla>0.2500</cla>
      <cda>0.10</cda>
      <cma>0.00</cma>
      <cla_stall>-0.025</cla_stall>
      <cda_stall>0.0</cda_stall>
      <cma_stall>0.0</cma_stall>
      <area>0.2</area>
      <air_density>1.2041</air_density>
      <cp>0.084 0 0</cp>
      <forward>0 1 0</forward>
      <upward>0 0 1</upward>
      <link_name>final_iris::rotor_1</link_name>
    </plugin>
  </gazebo>
  <gazebo>
    <plugin filename="libLiftDragPlugin.so" name="rotor_1_blade_2">
      <a0>0.1</a0>
      <alpha_stall>1.4</alpha_stall>
      <cla>0.2500</cla>
      <cda>0.10</cda>
      <cma>0.00</cma>
      <cla_stall>-0.025</cla_stall>
      <cda_stall>0.0</cda_stall>
      <cma_stall>0.0</cma_stall>
      <area>0.2</area>
      <air_density>1.2041</air_density>
      <cp>-0.084 0 0</cp>
      <forward>0 -1 0</forward>
      <upward>0 0 1</upward>
      <link_name>final_iris::rotor_1</link_name>
    </plugin>
  </gazebo>
  <gazebo>
    <plugin filename="libLiftDragPlugin.so" name="rotor_2_blade_1">
      <a0>0.1</a0>
      <alpha_stall>1.4</alpha_stall>
      <cla>0.2500</cla>
      <cda>0.10</cda>
      <cma>0.00</cma>
      <cla_stall>-0.025</cla_stall>
      <cda_stall>0.0</cda_stall>
      <cma_stall>0.0</cma_stall>
      <area>0.2</area>
      <air_density>1.2041</air_density>
      <cp>0.084 0 0</cp>
      <forward>0 -1 0</forward>
      <upward>0 0 1</upward>
      <link_name>final_iris::rotor_2</link_name>
    </plugin>
  </gazebo>
  <gazebo>
    <plugin filename="libLiftDragPlugin.so" name="rotor_2_blade_2">
      <a0>0.1</a0>
      <alpha_stall>1.4</alpha_stall>
      <cla>0.2500</cla>
      <cda>0.10</cda>
      <cma>0.00</cma>
      <cla_stall>-0.025</cla_stall>
      <cda_stall>0.0</cda_stall>
      <cma_stall>0.0</cma_stall>
      <area>0.2</area>
      <air_density>1.2041</air_density>
      <cp>-0.084 0 0</cp>
      <forward>0 1 0</forward>
      <upward>0 0 1</upward>
      <link_name>final_iris::rotor_2</link_name>
    </plugin>
  </gazebo>
  <gazebo>
    <plugin filename="libLiftDragPlugin.so" name="rotor_3_blade_1">
      <a0>0.1</a0>
      <alpha_stall>1.4</alpha_stall>
      <cla>0.2500</cla>
      <cda>0.10</cda>
      <cma>0.00</cma>
      <cla_stall>-0.025</cla_stall>
      <cda_stall>0.0</cda_stall>
      <cma_stall>0.0</cma_stall>
      <area>0.2</area>
      <air_density>1.2041</air_density>
      <cp>0.084 0 0</cp>
      <forward>0 -1 0</forward>
      <upward>0 0 1</upward>
      <link_name>final_iris::rotor_3</link_name>
    </plugin>
  </gazebo>
  <gazebo>
    <plugin filename="libLiftDragPlugin.so" name="rotor_3_blade_2">
      <a0>0.1</a0>
      <alpha_stall>1.4</alpha_stall>
      <cla>0.2500</cla>
      <cda>0.10</cda>
      <cma>0.00</cma>
      <cla_stall>-0.025</cla_stall>
      <cda_stall>0.0</cda_stall>
      <cma_stall>0.0</cma_stall>
      <area>0.2</area>
      <air_density>1.2041</air_density>
      <cp>-0.084 0 0</cp>
      <forward>0 1 0</forward>
      <upward>0 0 1</upward>
      <link_name>final_iris::rotor_3</link_name>
    </plugin>
  </gazebo>
  <gazebo>
    <plugin filename="libArduPilotPlugin.so" name="arducopter_plugin">
      <fdm_addr>127.0.0.1</fdm_addr>
      <fdm_port_in>9002</fdm_port_in>
      <fdm_port_out>9003</fdm_port_out>
      <modelXYZToAirplaneXForwardZDown>0 0 0 3.141593 0 0</modelXYZToAirplaneXForwardZDown>
      <gazeboXYZToNED>0 0 0 3.141593 0 0</gazeboXYZToNED>
      <imuName>final_iris::final_iris/imu_link::imu_sensor</imuName>
      <connectionTimeoutMaxCount>5</connectionTimeoutMaxCount>
      <control channel="0">
        <type>VELOCITY</type>
        <offset>0</offset>
        <p_gain>0.20</p_gain>
        <i_gain>0</i_gain>
        <d_gain>0</d_gain>
        <i_max>0</i_max>
        <i_min>0</i_min>
        <cmd_max>2.5</cmd_max>
        <cmd_min>-2.5</cmd_min>
        <jointName>final_iris::rotor_0_joint</jointName>
        <multiplier>838</multiplier>
        <controlVelocitySlowdownSim>1</controlVelocitySlowdownSim>
      </control>
      <control channel="1">
        <type>VELOCITY</type>
        <offset>0</offset>
        <p_gain>0.20</p_gain>
        <i_gain>0</i_gain>
        <d_gain>0</d_gain>
        <i_max>0</i_max>
        <i_min>0</i_min>
        <cmd_max>2.5</cmd_max>
        <cmd_min>-2.5</cmd_min>
        <jointName>final_iris::rotor_1_joint</jointName>
        <multiplier>838</multiplier>
        <controlVelocitySlowdownSim>1</controlVelocitySlowdownSim>
      </control>
      <control channel="2">
        <type>VELOCITY</type>
        <offset>0</offset>
        <p_gain>0.20</p_gain>
        <i_gain>0</i_gain>
        <d_gain>0</d_gain>
        <i_max>0</i_max>
        <i_min>0</i_min>
        <cmd_max>2.5</cmd_max>
        <cmd_min>-2.5</cmd_min>
        <jointName>final_iris::rotor_2_joint</jointName>
        <multiplier>-838</multiplier>
        <controlVelocitySlowdownSim>1</controlVelocitySlowdownSim>
      </control>
      <control channel="3">
        <type>VELOCITY</type>
        <offset>0</offset>
        <p_gain>0.20</p_gain>
        <i_gain>0</i_gain>
        <d_gain>0</d_gain>
        <i_max>0</i_max>
        <i_min>0</i_min>
        <cmd_max>2.5</cmd_max>
        <cmd_min>-2.5</cmd_min>
        <jointName>final_iris::rotor_3_joint</jointName>
        <multiplier>-838</multiplier>
        <controlVelocitySlowdownSim>1</controlVelocitySlowdownSim>
      </control>
    </plugin>
  </gazebo>
</robot>

